Workbook
Name _BIR60: #REF!
Name _DAT1: #REF!
Name _DAT10: #REF!
Name _DAT11: #REF!
Name _DAT12: #REF!
Name _DAT13: #REF!
Name _DAT14: #REF!
Name _DAT15: #REF!
Name _DAT2: #REF!
Name _DAT3: #REF!
Name _DAT4: #REF!
Name _DAT5: #REF!
Name _DAT6: #REF!
Name _DAT7: #REF!
Name _DAT8: #REF!
Name _DAT9: #REF!
Name _new1: #REF!
Name _tax1: #REF!
Name _tax2: #REF!
Name _tax3: #REF!
Name BIR60_Page1: #REF!
Name BIR60_Page2: #REF!
Name BIR60_Page3: #REF!
Name BIR60_Page4: #REF!
Name BIR60_Page5: #REF!
Name BIR60_Print: #REF!
Name BIR60_PrintF: #REF!
Name BIR60_PrintF2: #REF!
Name BIR60App_PrintF: #REF!
Name comp1: #REF!
Name comp2: #REF!
Name comp3: #REF!
Name Company_Details: #REF!
Name Gross_Up: #REF!
Name Grossup: #REF!
Name HKD: #REF!
Name Income_for_tax_at_standard_rate: #REF!
Name Input_10a: #REF!
Name Input_10b: #REF!
Name Input_10c: #REF!
Name Input_10d: #REF!
Name Input_1a: #REF!
Name Input_1b: #REF!
Name Input_1c: #REF!
Name Input_1d: #REF!
Name Input_2a: #REF!
Name Input_2b: #REF!
Name Input_2c: #REF!
Name Input_2d: #REF!
Name Input_3a: #REF!
Name Input_3b: #REF!
Name Input_3c: #REF!
Name Input_3d: #REF!
Name Input_4a: #REF!
Name Input_4b: #REF!
Name Input_4c: #REF!
Name Input_4d: #REF!
Name Input_5a: #REF!
Name Input_5b: #REF!
Name Input_5c: #REF!

Sheet Balance Sheet
A1: International Assignment Balance Sheet
A3: Name: 张文乐 | I3: Exchange rate
A4: Entry to Brazil：2025/6/24 | I4: 46023 | J4: 1.3393
A5: Currency：CNY | I5: 46054 | J5: 1.3346
A6: Assignment Period: 2025/6/23 to 2027/6/30 | I6: 46082 | J6: 1.3166
B8: EOR | C8: EOR | D8: EOR离职 | E8: Transfer至Keeta | F8: Keeta | G8: Keeta
A9: Total Global Package 全球薪酬 | B9: 46023 | C9: 46054 | D9: 46082 | E9: 46113 | F9: 46143 | G9: 46174 | I9: 46113 | J9: 1.3701
A10: Gross Income-CNY | I10: 46143 | J10: 1.3439
A11: 基本工资 | B11: 42710 | C11: 42710 | D11: 42710 | E11: 42710 | F11: 42710 | G11: 42710 | I11: 46174 | J11: 1.3142
A12: 激励奖金 | B12: 21355 | C12: 17084 | D12: 21355 | E12: 21355 | F12: 21355 | G12: 21355
A13: Subtotal Gross Income | B13: =SUM(B11:B12) -> 64065 | C13: =SUM(C11:C12) -> 59794 | D13: =SUM(D11:D12) -> 64065 | E13: =SUM(E11:E12) -> 64065 | F13: =SUM(F11:F12) -> 64065 | G13: =SUM(G11:G12) -> 64065
A15: Net Income -CNY
A16: Expat Allowance for Assignment 外派津贴 | B16: 43000 | C16: 43000 | D16: 43000 | E16: 43000 | F16: 43000 | G16: 43000
A17: Net Income -BRL
A18: Housing Subsidy for Assignment 住房补贴 | B18: 住公司公寓，在housing allowance (BRL10,000)和公寓租金之间多退少补。该政策，如沟通，2026年6月30日失效，之前期间的多退少补金额(BRL22,416.93)会在8月巴西工资发放。20 days in January + 5 months (Feb to Jun)
A19: Subtotal Net Income | B19: =B16 -> 43000 | C19: =C16 -> 43000 | D19: =D16 -> 43000 | E19: =E16 -> 43000 | F19: =F16 -> 43000 | G19: =G16 -> 43000
A21: Minus:
A22: Home social security-Employee Contribution 社保个人供款部分 | B22: =假设税计算!C12 -> -2362.66 | C22: =假设税计算!D12 -> -2362.66 | D22: =假设税计算!E12 -> -2362.66 | E22: =假设税计算!F12 -> -2362.66 | F22: =假设税计算!G12 -> -2362.66 | G22: =假设税计算!H12 -> -2362.66
A23: Home Housing Fund-Employee Contribution 住房公积金个人供款部分 | B23: =假设税计算!C13 -> -3882 | C23: =假设税计算!D13 -> -3882 | D23: =假设税计算!E13 -> -3882 | E23: =假设税计算!F13 -> -3882 | F23: =假设税计算!G13 -> -3882 | G23: =假设税计算!H13 -> -3882
A24: Hypo tax 假设税 | B24: 0 | C24: 0 | D24: 0 | E24: =-假设税计算!$N$31 -> -13816.98 | F24: =-假设税计算!$N$31 -> -13816.98 | G24: =-假设税计算!$N$31 -> -13816.98
A25: 个税补偿 | B25: 9243.29 | C25: 0 | D25: 4859.59 | E25: 10713.78 | F25: 11017.2 | G25: 12612.72
A26: 个税扣减 - 月度缴纳个税 | B26: -15437.17 | C26: -5926.13 | D26: -15403.66 | E26: -10713.78 | F26: -11017.2 | G26: -12612.72
A27: 公益月捐 | B27: -100 | C27: -100 | D27: -100 | E27: -100 | F27: -100 | G27: -100
A28: Subtotal | B28: =SUM(B22:B27) -> -12538.54 | C28: =SUM(C22:C27) -> -12270.79 | D28: =SUM(D22:D27) -> -16888.73 | E28: =SUM(E22:E27) -> -20161.64 | F28: =SUM(F22:F27) -> -20161.64 | G28: =SUM(G22:G27) -> -20161.64
A30: Employee take home globally-CNY | B30: =B13+B19+B28 -> 94526.46 | C30: =C13+C19+C28 -> 90523.21 | D30: =D13+D19+D28 -> 90176.27 | E30: =E13+E19+E28 -> 86903.36 | F30: =F13+F19+F28 -> 86903.36 | G30: =G13+G19+G28 -> 86903.36
A32: Employee take home in China 员工实收-中国 | B32: 46023 | C32: 46054 | D32: 46082 | E32: 46113 | F32: 46143 | G32: 46174
A33: Gross Income-CNY
A34: 基本工资 | B34: 42710 | C34: 42710 | D34: 42710 | E34: 42710 | F34: 42710 | G34: 42710
A35: 激励奖金 | B35: 21355 | C35: 17084 | D35: 21355 | E35: 21355 | F35: 21355 | G35: 21355
A36: Subtotal Gross Income | B36: =SUM(B34:B35) -> 64065 | C36: =SUM(C34:C35) -> 59794 | D36: =SUM(D34:D35) -> 64065 | E36: =SUM(E34:E35) -> 64065 | F36: =SUM(F34:F35) -> 64065 | G36: =SUM(G34:G35) -> 64065
A38: Net Income -CNY (这部分体现在工资单“外派津贴”)
A39: Expat Allowance for Assignment 外派津贴 | B39: =B16 -> 43000 | C39: =C16 -> 43000 | D39: =D16 -> 43000 | E39: =E16 -> 43000 | F39: =F16 -> 43000 | G39: =G16 -> 43000
A40: Pay-out in Host location 巴西发放的工资 | B40: =ROUND(-(B60+B63)*J4,2) -> -6026.85 | C40: =ROUND(-(C60+C63)*J5,2) -> -61818.67 | D40: =ROUND(-(D60+D63+D68)*J6,2) -> -24778.41 | E40: =ROUND(-(E60+E63)*J9,2) -> -49762.03 | F40: =ROUND(-(F60+F63)*J10,2) -> -48851.77 | G40: =ROUND(-(G60+G63)*J11,2) -> -47772.16
A41: Subtotal Net income | B41: =SUM(B39:B40) -> 36973.15 | C41: =SUM(C39:C40) -> -18818.67 | D41: =SUM(D39:D40) -> 18221.59 | E41: =SUM(E39:E40) -> -6762.03 | F41: =SUM(F39:F40) -> -5851.77 | G41: =SUM(G39:G40) -> -4772.16
A43: Minus:
A44: Home social security-Employee Contribution 社保个人供款部分 | B44: -2362.66 | C44: -2362.66 | D44: -2362.66 | E44: -2362.66 | F44: -2362.66 | G44: -2362.66
A45: Home Housing Fund-Employee Contribution 住房公积金个人供款部分 | B45: -3882 | C45: -3882 | D45: -3882 | E45: -3882 | F45: -3882 | G45: -3882
A46: Hypo tax 假设税 | B46: 0 | C46: 0 | D46: 0 | E46: =-假设税计算!$N$31 -> -13816.98 | F46: =-假设税计算!$N$31 -> -13816.98 | G46: =-假设税计算!$N$31 -> -13816.98
A47: 个税补偿 | B47: 9243.29 | C47: 0 | D47: 4859.59 | E47: 10713.78 | F47: 11017.2 | G47: 12612.72
A48: 个税扣减 - 月度缴纳个税 | B48: -15437.17 | C48: -5926.13 | D48: -15403.66 | E48: -10713.78 | F48: -11017.2 | G48: -12612.72
...

Sheet 假设税计算
A1: 假设税计算
A3: 工资所属期 | B3: 45992 | C3: 46023 | D3: 46054 | E3: 46082 | F3: 46113 | G3: 46143 | H3: 46174 | I3: 46204 | J3: 46235 | K3: 46266 | L3: 46296 | M3: 46327
A5: 纳税申报所属期&工资发放所属月份 | B5: 46023 | C5: 46054 | D5: 46082 | E5: 46113 | F5: 46143 | G5: 46174 | H5: 46204 | I5: 46235 | J5: 46266 | K5: 46296 | L5: 46327 | M5: 46357 | N5: 年度累计
A7: Gross Income
A8: 基本工资 | B8: 42710 | C8: 42710 | D8: 42710 | E8: 42710 | F8: 42710 | G8: 42710 | H8: 42710 | I8: 42710 | J8: 42710 | K8: 42710 | L8: 42710 | M8: 42710 | N8: =SUM(B8:M8) -> 512520
A9: 激励奖金 | B9: 21355 | C9: 21355 | D9: 17084 | E9: 21355 | F9: 21355 | G9: 21355 | H9: 21355 | I9: 21355 | J9: 21355 | K9: 21355 | L9: 21355 | M9: 21355 | N9: =SUM(B9:M9) -> 251989
A10: 小计 | B10: =SUM(B8:B9) -> 64065 | C10: =SUM(C8:C9) -> 64065 | D10: =SUM(D8:D9) -> 59794 | E10: =SUM(E8:E9) -> 64065 | F10: =SUM(F8:F9) -> 64065 | G10: =SUM(G8:G9) -> 64065 | H10: =SUM(H8:H9) -> 64065 | I10: =SUM(I8:I9) -> 64065 | ... M10: =SUM(M8:M9) -> 64065 | N10: =SUM(B10:M10) -> 764509
A12: 社保个人缴纳 | B12: =ROUND(-'[1]中国社保缴费比例&上下限'!$G$54,2) -> -2362.66 | C12: =ROUND(-'[1]中国社保缴费比例&上下限'!$G$54,2) -> -2362.66 | D12: =ROUND(-'[1]中国社保缴费比例&上下限'!$G$54,2) -> -2362.66 | E12: =ROUND(-'[1]中国社保缴费比例&上下限'!$G$54,2) -> -2362.66 | F12: =ROUND(-'[1]中国社保缴费比例&上下限'!$G$54,2) -> -2362.66 | G12: =ROUND(-'[1]中国社保缴费比例&上下限'!$G$54,2) -> -2362.66 | H12: =ROUND(-'[1]中国社保缴费比例&上下限'!$G$54,2) -> -2362.66 | I12: =ROUND(-'[1]中国社保缴费比例&上下限'!$G$54,2) -> -2362.66 | ... M12: =ROUND(-'[1]中国社保缴费比例&上下限'!$G$54,2) -> -2362.66 | N12: =SUM(B12:M12) -> -28351.92
A13: 住房公积金个人缴纳 | B13: =-'[1]中国社保缴费比例&上下限'!$G$55 -> -3882 | C13: =-'[1]中国社保缴费比例&上下限'!$G$55 -> -3882 | D13: =-'[1]中国社保缴费比例&上下限'!$G$55 -> -3882 | E13: =-'[1]中国社保缴费比例&上下限'!$G$55 -> -3882 | F13: =-'[1]中国社保缴费比例&上下限'!$G$55 -> -3882 | G13: =-'[1]中国社保缴费比例&上下限'!$G$55 -> -3882 | H13: =-'[1]中国社保缴费比例&上下限'!$G$55 -> -3882 | I13: =-'[1]中国社保缴费比例&上下限'!$G$55 -> -3882 | ... M13: =-'[1]中国社保缴费比例&上下限'!$G$55 -> -3882 | N13: =SUM(B13:M13) -> -46584
A14: 小计 | N14: =SUM(N12:N13) -> -74935.92
A16: 标准扣除 | B16: -5000 | C16: -5000 | D16: -5000 | E16: -5000 | F16: -5000 | G16: -5000 | H16: -5000 | I16: -5000 | J16: -5000 | K16: -5000 | L16: -5000 | M16: -5000 | N16: =SUM(B16:M16) -> -60000
A18: 累计应纳税所得额 | N18: =N10+N14+N16 -> 629573.08
A19: 税率 | N19: =VLOOKUP(N18,[1]中国税率表!$A$1:$D$7,3) -> 0.3
A20: 速算扣除数 | N20: =VLOOKUP(N18,[1]中国税率表!$A$1:$D$7,4) -> 52920
A21: 累计应纳税额 | N21: =N18*N19-N20 -> 135951.92
A23: Hypo tax 假设税 | B23: 0 | C23: 0 | D23: 0 | E23: 0 | F23: -13816.98 | G23: -13816.98 | H23: -13816.98
A24: 个税补偿 | B24: 4777.78 | C24: 9243.29 | D24: 0 | E24: 4859.59 | F24: 10713.78 | G24: 11017.2 | H24: 12612.72
A25: 个税扣减 | B25: -7529.81 | C25: -15437.17 | D25: -5926.13 | E25: -15403.66 | F25: -10713.78 | G25: -11017.2 | H25: -12612.72
A27: 累计扣除假设税 | N27: =SUM(B23:E23) -> 0
A28: 累计个税补贴 | N28: =SUM(B24:E24) -> 18880.66
A29: 累计薪金税 | N29: =-SUM(B25:E25) -> 44296.77
A31: 月度假设税金额 | N31: =ROUND((N21-(N29-N28+N27))/(12-5+1),2) -> 13816.98
A33: 备注：
A34: 1. 假设税计算逻辑是按照纳税申报所属期的收入进行计算（比如，25年12月工资的发放和申报月份是26年1月，计算假设税时，考虑的是实际工资所属期25年12月到26年11月的工资收入。）
A35: 2. 假设税计算是根据月度公司税款申报系统所抓取到的员工填写的专项附加扣除进行考虑。如果员工月度没有填写专项附加扣除，假设税计算时，也将不会考虑。
